[27/Mar/2018 20:13:34] "POST /receive?signature=093e2336d359ea2e5e94c2aae9cc01683de19b2a&timestamp=1522152813&nonce=921927004&openid=o23eNv5yOlj-dgeMOk8GxyUsviHA HTTP/1.1" 200 272
Internal Server Error: /receive
Traceback (most recent call last):
  File "/usr/local/lib/python3.5/dist-packages/django/utils/datastructures.py", line 77, in __getitem__
    list_ = super().__getitem__(key)
KeyError: 'echostr'

During handling of the above exception, another exception occurred:

Traceback (most recent call last):
  File "/home/WeWallProject/WeWall/views.py", line 17, in receive
    echostr = request.GET['echostr'];
  File "/usr/local/lib/python3.5/dist-packages/django/utils/datastructures.py", line 79, in __getitem__
    raise MultiValueDictKeyError(key)
django.utils.datastructures.MultiValueDictKeyError: 'echostr'

During handling of the above exception, another exception occurred:

Traceback (most recent call last):
  File "/usr/local/lib/python3.5/dist-packages/django/core/handlers/exception.py", line 35, in inner
    response = get_response(request)
  File "/usr/local/lib/python3.5/dist-packages/django/core/handlers/base.py", line 128, in _get_response
    response = self.process_exception_by_middleware(e, request)
  File "/usr/local/lib/python3.5/dist-packages/django/core/handlers/base.py", line 126, in _get_response
    response = wrapped_callback(request, *callback_args, **callback_kwargs)
  File "/home/WeWallProject/WeWall/views.py", line 39, in receive
    cursor.execute("INSERT INTO wewall_msg (content, userID, checked, danmu, wall) VALUES ('%s', '%s', false, false, false)" %(content, username))
  File "/usr/local/lib/python3.5/dist-packages/pymysql/cursors.py", line 165, in execute
    result = self._query(query)
  File "/usr/local/lib/python3.5/dist-packages/pymysql/cursors.py", line 321, in _query
    conn.query(q)
  File "/usr/local/lib/python3.5/dist-packages/pymysql/connections.py", line 860, in query
    self._affected_rows = self._read_query_result(unbuffered=unbuffered)
  File "/usr/local/lib/python3.5/dist-packages/pymysql/connections.py", line 1061, in _read_query_result
    result.read()
  File "/usr/local/lib/python3.5/dist-packages/pymysql/connections.py", line 1349, in read
    first_packet = self.connection._read_packet()
  File "/usr/local/lib/python3.5/dist-packages/pymysql/connections.py", line 1018, in _read_packet
    packet.check_error()
  File "/usr/local/lib/python3.5/dist-packages/pymysql/connections.py", line 384, in check_error
    err.raise_mysql_exception(self._data)
  File "/usr/local/lib/python3.5/dist-packages/pymysql/err.py", line 107, in raise_mysql_exception
    raise errorclass(errno, errval)
pymysql.err.ProgrammingError: (1064, "You have an error in your SQL syntax; check the manual that corresponds to your MySQL server version for the right syntax to use near 'o23eNv5yOlj-dgeMOk8GxyUsviHA', false, false, false)' at line 1")
[27/Mar/2018 20:13:40] "POST /receive?signature=9da31af9f7a7336756481b061dc505c076cb792e&timestamp=1522152819&nonce=767083575&openid=o23eNv5yOlj-dgeMOk8GxyUsviHA HTTP/1.1" 500 127060
[27/Mar/2018 20:13:51] "POST /receive?signature=be6d25731ff94a10ea55ed272d84dd6b932b68b6&timestamp=1522152830&nonce=1949366561&openid=o23eNv5yOlj-dgeMOk8GxyUsviHA HTTP/1.1" 200 272
Performing system checks...

System check identified no issues (0 silenced).

You have 14 unapplied migration(s). Your project may not work properly until you apply the migrations for app(s): admin, auth, contenttypes, sessions.
Run 'python manage.py migrate' to apply them.
March 27, 2018 - 20:13:18
Django version 2.0.3, using settings 'WeWallProject.settings'
Starting development server at http://0:80/
Quit the server with CONTROL-C.
b'<xml><ToUserName><![CDATA[gh_0293d1e9bd7c]]></ToUserName>\n<FromUserName><![CDATA[o23eNv5yOlj-dgeMOk8GxyUsviHA]]></FromUserName>\n<CreateTime>1522152813</CreateTime>\n<MsgType><![CDATA[text]]></MsgType>\n<Content><![CDATA[uu]]></Content>\n<MsgId>6537596551776706393</MsgId>\n</xml>'
uu
uu
<xml><ToUserName><![CDATA[o23eNv5yOlj-dgeMOk8GxyUsviHA]]></ToUserName><FromUserName><![CDATA[gh_0293d1e9bd7c]]></FromUserName><CreateTime>1522152814</CreateTime><MsgType><![CDATA[text]]></MsgType><Content><![CDATA[你的消息已发送，请等待审核]]></Content></xml>
b"<xml><ToUserName><![CDATA[gh_0293d1e9bd7c]]></ToUserName>\n<FromUserName><![CDATA[o23eNv5yOlj-dgeMOk8GxyUsviHA]]></FromUserName>\n<CreateTime>1522152819</CreateTime>\n<MsgType><![CDATA[text]]></MsgType>\n<Content><![CDATA[']]></Content>\n<MsgId>6537596577546510171</MsgId>\n</xml>"
'
'
b'<xml><ToUserName><![CDATA[gh_0293d1e9bd7c]]></ToUserName>\n<FromUserName><![CDATA[o23eNv5yOlj-dgeMOk8GxyUsviHA]]></FromUserName>\n<CreateTime>1522152830</CreateTime>\n<MsgType><![CDATA[text]]></MsgType>\n<Content><![CDATA[dr]]></Content>\n<MsgId>6537596624791150432</MsgId>\n</xml>'
dr
dr
<xml><ToUserName><![CDATA[o23eNv5yOlj-dgeMOk8GxyUsviHA]]></ToUserName><FromUserName><![CDATA[gh_0293d1e9bd7c]]></FromUserName><CreateTime>1522152831</CreateTime><MsgType><![CDATA[text]]></MsgType><Content><![CDATA[你的消息已发送，请等待审核]]></Content></xml>
[27/Mar/2018 20:14:22] "POST /receive?signature=bcd3f3766b68d993b32c28c6f2e0e51462ee62ed&timestamp=1522152862&nonce=1324849006&openid=o23eNv5yOlj-dgeMOk8GxyUsviHA HTTP/1.1" 200 272
[27/Mar/2018 20:14:25] "POST /receive?signature=68f9f275014fb2bdaa46c32faa05f127cc710e2e&timestamp=1522152864&nonce=2080759167&openid=o23eNv5yOlj-dgeMOk8GxyUsviHA HTTP/1.1" 200 272
[27/Mar/2018 20:14:41] "POST /receive?signature=550befbd1f274f3aec70db1f8dc91ac1e0dc98d3&timestamp=1522152880&nonce=789020612&openid=o23eNv5yOlj-dgeMOk8GxyUsviHA HTTP/1.1" 200 272
Invalid HTTP_HOST header: 'www.baidu.com'. You may need to add 'www.baidu.com' to ALLOWED_HOSTS.
[27/Mar/2018 20:44:21] "GET http://www.baidu.com/cache/global/img/gs.gif HTTP/1.1" 400 58634
Invalid HTTP_HOST header: 'www.dingzheng214.xin'. You may need to add 'www.dingzheng214.xin' to ALLOWED_HOSTS.
[27/Mar/2018 20:53:27] "GET /robots.txt HTTP/1.1" 400 59377
Traceback (most recent call last):
  File "/usr/lib/python3.5/wsgiref/handlers.py", line 138, in run
    self.finish_response()
  File "/usr/lib/python3.5/wsgiref/handlers.py", line 180, in finish_response
    self.write(data)
  File "/usr/lib/python3.5/wsgiref/handlers.py", line 274, in write
    self.send_headers()
  File "/usr/lib/python3.5/wsgiref/handlers.py", line 332, in send_headers
    self.send_preamble()
  File "/usr/lib/python3.5/wsgiref/handlers.py", line 252, in send_preamble
    self._write(('HTTP/%s %s\r\n' % (self.http_version,self.status)).encode('iso-8859-1'))
  File "/usr/lib/python3.5/wsgiref/handlers.py", line 453, in _write
    result = self.stdout.write(data)
  File "/usr/lib/python3.5/socket.py", line 593, in write
    return self._sock.send(b)
ConnectionResetError: [Errno 104] Connection reset by peer
[27/Mar/2018 20:53:27] "GET /robots.txt HTTP/1.1" 500 59
Traceback (most recent call last):
  File "/usr/lib/python3.5/wsgiref/handlers.py", line 138, in run
    self.finish_response()
  File "/usr/lib/python3.5/wsgiref/handlers.py", line 180, in finish_response
    self.write(data)
  File "/usr/lib/python3.5/wsgiref/handlers.py", line 274, in write
    self.send_headers()
  File "/usr/lib/python3.5/wsgiref/handlers.py", line 332, in send_headers
    self.send_preamble()
  File "/usr/lib/python3.5/wsgiref/handlers.py", line 252, in send_preamble
    self._write(('HTTP/%s %s\r\n' % (self.http_version,self.status)).encode('iso-8859-1'))
  File "/usr/lib/python3.5/wsgiref/handlers.py", line 453, in _write
    result = self.stdout.write(data)
  File "/usr/lib/python3.5/socket.py", line 593, in write
    return self._sock.send(b)
ConnectionResetError: [Errno 104] Connection reset by peer

During handling of the above exception, another exception occurred:

Traceback (most recent call last):
  File "/usr/lib/python3.5/wsgiref/handlers.py", line 141, in run
    self.handle_error()
  File "/usr/local/lib/python3.5/dist-packages/django/core/servers/basehttp.py", line 86, in handle_error
    super().handle_error()
  File "/usr/lib/python3.5/wsgiref/handlers.py", line 368, in handle_error
    self.finish_response()
  File "/usr/lib/python3.5/wsgiref/handlers.py", line 180, in finish_response
    self.write(data)
  File "/usr/lib/python3.5/wsgiref/handlers.py", line 274, in write
    self.send_headers()
  File "/usr/lib/python3.5/wsgiref/handlers.py", line 331, in send_headers
    if not self.origin_server or self.client_is_modern():
  File "/usr/lib/python3.5/wsgiref/handlers.py", line 344, in client_is_modern
    return self.environ['SERVER_PROTOCOL'].upper() != 'HTTP/0.9'
TypeError: 'NoneType' object is not subscriptable

During handling of the above exception, another exception occurred:

Traceback (most recent call last):
  File "/usr/lib/python3.5/socketserver.py", line 625, in process_request_thread
    self.finish_request(request, client_address)
  File "/usr/lib/python3.5/socketserver.py", line 354, in finish_request
    self.RequestHandlerClass(request, client_address, self)
  File "/usr/lib/python3.5/socketserver.py", line 681, in __init__
    self.handle()
  File "/usr/local/lib/python3.5/dist-packages/django/core/servers/basehttp.py", line 154, in handle
    handler.run(self.server.get_app())
  File "/usr/lib/python3.5/wsgiref/handlers.py", line 144, in run
    self.close()
  File "/usr/lib/python3.5/wsgiref/simple_server.py", line 36, in close
    self.status.split(' ',1)[0], self.bytes_sent
AttributeError: 'NoneType' object has no attribute 'split'
Invalid HTTP_HOST header: 'www.dingzheng214.xin'. You may need to add 'www.dingzheng214.xin' to ALLOWED_HOSTS.
[27/Mar/2018 20:53:28] "GET / HTTP/1.1" 400 59256
Traceback (most recent call last):
  File "/usr/lib/python3.5/wsgiref/handlers.py", line 138, in run
    self.finish_response()
  File "/usr/lib/python3.5/wsgiref/handlers.py", line 180, in finish_response
    self.write(data)
  File "/usr/lib/python3.5/wsgiref/handlers.py", line 274, in write
    self.send_headers()
  File "/usr/lib/python3.5/wsgiref/handlers.py", line 332, in send_headers
    self.send_preamble()
  File "/usr/lib/python3.5/wsgiref/handlers.py", line 252, in send_preamble
    self._write(('HTTP/%s %s\r\n' % (self.http_version,self.status)).encode('iso-8859-1'))
  File "/usr/lib/python3.5/wsgiref/handlers.py", line 453, in _write
    result = self.stdout.write(data)
  File "/usr/lib/python3.5/socket.py", line 593, in write
    return self._sock.send(b)
ConnectionResetError: [Errno 104] Connection reset by peer
[27/Mar/2018 20:53:28] "GET / HTTP/1.1" 500 59
Traceback (most recent call last):
  File "/usr/lib/python3.5/wsgiref/handlers.py", line 138, in run
    self.finish_response()
  File "/usr/lib/python3.5/wsgiref/handlers.py", line 180, in finish_response
    self.write(data)
  File "/usr/lib/python3.5/wsgiref/handlers.py", line 274, in write
    self.send_headers()
  File "/usr/lib/python3.5/wsgiref/handlers.py", line 332, in send_headers
    self.send_preamble()
  File "/usr/lib/python3.5/wsgiref/handlers.py", line 252, in send_preamble
    self._write(('HTTP/%s %s\r\n' % (self.http_version,self.status)).encode('iso-8859-1'))
  File "/usr/lib/python3.5/wsgiref/handlers.py", line 453, in _write
    result = self.stdout.write(data)
  File "/usr/lib/python3.5/socket.py", line 593, in write
    return self._sock.send(b)
ConnectionResetError: [Errno 104] Connection reset by peer

During handling of the above exception, another exception occurred:

Traceback (most recent call last):
  File "/usr/lib/python3.5/wsgiref/handlers.py", line 141, in run
    self.handle_error()
  File "/usr/local/lib/python3.5/dist-packages/django/core/servers/basehttp.py", line 86, in handle_error
    super().handle_error()
  File "/usr/lib/python3.5/wsgiref/handlers.py", line 368, in handle_error
    self.finish_response()
  File "/usr/lib/python3.5/wsgiref/handlers.py", line 180, in finish_response
    self.write(data)
  File "/usr/lib/python3.5/wsgiref/handlers.py", line 274, in write
    self.send_headers()
  File "/usr/lib/python3.5/wsgiref/handlers.py", line 331, in send_headers
    if not self.origin_server or self.client_is_modern():
  File "/usr/lib/python3.5/wsgiref/handlers.py", line 344, in client_is_modern
    return self.environ['SERVER_PROTOCOL'].upper() != 'HTTP/0.9'
TypeError: 'NoneType' object is not subscriptable

During handling of the above exception, another exception occurred:

Traceback (most recent call last):
  File "/usr/lib/python3.5/socketserver.py", line 625, in process_request_thread
    self.finish_request(request, client_address)
  File "/usr/lib/python3.5/socketserver.py", line 354, in finish_request
    self.RequestHandlerClass(request, client_address, self)
  File "/usr/lib/python3.5/socketserver.py", line 681, in __init__
    self.handle()
  File "/usr/local/lib/python3.5/dist-packages/django/core/servers/basehttp.py", line 154, in handle
    handler.run(self.server.get_app())
  File "/usr/lib/python3.5/wsgiref/handlers.py", line 144, in run
    self.close()
  File "/usr/lib/python3.5/wsgiref/simple_server.py", line 36, in close
    self.status.split(' ',1)[0], self.bytes_sent
AttributeError: 'NoneType' object has no attribute 'split'
Invalid HTTP_HOST header: 'www.dingzheng214.xin'. You may need to add 'www.dingzheng214.xin' to ALLOWED_HOSTS.
[27/Mar/2018 20:53:28] "GET / HTTP/1.1" 400 58542
Traceback (most recent call last):
  File "/usr/lib/python3.5/wsgiref/handlers.py", line 138, in run
    self.finish_response()
  File "/usr/lib/python3.5/wsgiref/handlers.py", line 180, in finish_response
    self.write(data)
  File "/usr/lib/python3.5/wsgiref/handlers.py", line 274, in write
    self.send_headers()
  File "/usr/lib/python3.5/wsgiref/handlers.py", line 332, in send_headers
    self.send_preamble()
  File "/usr/lib/python3.5/wsgiref/handlers.py", line 252, in send_preamble
    self._write(('HTTP/%s %s\r\n' % (self.http_version,self.status)).encode('iso-8859-1'))
  File "/usr/lib/python3.5/wsgiref/handlers.py", line 453, in _write
    result = self.stdout.write(data)
  File "/usr/lib/python3.5/socket.py", line 593, in write
    return self._sock.send(b)
ConnectionResetError: [Errno 104] Connection reset by peer
[27/Mar/2018 20:53:28] "GET / HTTP/1.1" 500 59
Traceback (most recent call last):
  File "/usr/lib/python3.5/wsgiref/handlers.py", line 138, in run
    self.finish_response()
  File "/usr/lib/python3.5/wsgiref/handlers.py", line 180, in finish_response
    self.write(data)
  File "/usr/lib/python3.5/wsgiref/handlers.py", line 274, in write
    self.send_headers()
  File "/usr/lib/python3.5/wsgiref/handlers.py", line 332, in send_headers
    self.send_preamble()
  File "/usr/lib/python3.5/wsgiref/handlers.py", line 252, in send_preamble
    self._write(('HTTP/%s %s\r\n' % (self.http_version,self.status)).encode('iso-8859-1'))
  File "/usr/lib/python3.5/wsgiref/handlers.py", line 453, in _write
    result = self.stdout.write(data)
  File "/usr/lib/python3.5/socket.py", line 593, in write
    return self._sock.send(b)
ConnectionResetError: [Errno 104] Connection reset by peer

During handling of the above exception, another exception occurred:

Traceback (most recent call last):
  File "/usr/lib/python3.5/wsgiref/handlers.py", line 141, in run
    self.handle_error()
  File "/usr/local/lib/python3.5/dist-packages/django/core/servers/basehttp.py", line 86, in handle_error
    super().handle_error()
  File "/usr/lib/python3.5/wsgiref/handlers.py", line 368, in handle_error
    self.finish_response()
  File "/usr/lib/python3.5/wsgiref/handlers.py", line 180, in finish_response
    self.write(data)
  File "/usr/lib/python3.5/wsgiref/handlers.py", line 274, in write
    self.send_headers()
  File "/usr/lib/python3.5/wsgiref/handlers.py", line 331, in send_headers
    if not self.origin_server or self.client_is_modern():
  File "/usr/lib/python3.5/wsgiref/handlers.py", line 344, in client_is_modern
    return self.environ['SERVER_PROTOCOL'].upper() != 'HTTP/0.9'
TypeError: 'NoneType' object is not subscriptable

During handling of the above exception, another exception occurred:

Traceback (most recent call last):
  File "/usr/lib/python3.5/socketserver.py", line 625, in process_request_thread
    self.finish_request(request, client_address)
  File "/usr/lib/python3.5/socketserver.py", line 354, in finish_request
    self.RequestHandlerClass(request, client_address, self)
  File "/usr/lib/python3.5/socketserver.py", line 681, in __init__
    self.handle()
  File "/usr/local/lib/python3.5/dist-packages/django/core/servers/basehttp.py", line 154, in handle
    handler.run(self.server.get_app())
  File "/usr/lib/python3.5/wsgiref/handlers.py", line 144, in run
    self.close()
  File "/usr/lib/python3.5/wsgiref/simple_server.py", line 36, in close
    self.status.split(' ',1)[0], self.bytes_sent
AttributeError: 'NoneType' object has no attribute 'split'
Invalid HTTP_HOST header: 'iZ2zec2th4yjgeqo5hka6mZ'. You may need to add 'iz2zec2th4yjgeqo5hka6mz' to ALLOWED_HOSTS.
[27/Mar/2018 21:12:02] "GET / HTTP/1.0" 400 58184
Traceback (most recent call last):
  File "/usr/lib/python3.5/wsgiref/handlers.py", line 138, in run
    self.finish_response()
  File "/usr/lib/python3.5/wsgiref/handlers.py", line 180, in finish_response
    self.write(data)
  File "/usr/lib/python3.5/wsgiref/handlers.py", line 279, in write
    self._write(data)
  File "/usr/lib/python3.5/wsgiref/handlers.py", line 463, in _write
    result = self.stdout.write(data)
  File "/usr/lib/python3.5/socket.py", line 593, in write
    return self._sock.send(b)
ConnectionResetError: [Errno 104] Connection reset by peer
[27/Mar/2018 21:12:02] "GET / HTTP/1.0" 500 59
Traceback (most recent call last):
  File "/usr/lib/python3.5/wsgiref/handlers.py", line 138, in run
    self.finish_response()
  File "/usr/lib/python3.5/wsgiref/handlers.py", line 180, in finish_response
    self.write(data)
  File "/usr/lib/python3.5/wsgiref/handlers.py", line 279, in write
    self._write(data)
  File "/usr/lib/python3.5/wsgiref/handlers.py", line 463, in _write
    result = self.stdout.write(data)
  File "/usr/lib/python3.5/socket.py", line 593, in write
    return self._sock.send(b)
ConnectionResetError: [Errno 104] Connection reset by peer

During handling of the above exception, another exception occurred:

Traceback (most recent call last):
  File "/usr/lib/python3.5/wsgiref/handlers.py", line 141, in run
    self.handle_error()
  File "/usr/local/lib/python3.5/dist-packages/django/core/servers/basehttp.py", line 86, in handle_error
    super().handle_error()
  File "/usr/lib/python3.5/wsgiref/handlers.py", line 368, in handle_error
    self.finish_response()
  File "/usr/lib/python3.5/wsgiref/handlers.py", line 180, in finish_response
    self.write(data)
  File "/usr/lib/python3.5/wsgiref/handlers.py", line 274, in write
    self.send_headers()
  File "/usr/lib/python3.5/wsgiref/handlers.py", line 331, in send_headers
    if not self.origin_server or self.client_is_modern():
  File "/usr/lib/python3.5/wsgiref/handlers.py", line 344, in client_is_modern
    return self.environ['SERVER_PROTOCOL'].upper() != 'HTTP/0.9'
TypeError: 'NoneType' object is not subscriptable

During handling of the above exception, another exception occurred:

Traceback (most recent call last):
  File "/usr/lib/python3.5/socketserver.py", line 625, in process_request_thread
    self.finish_request(request, client_address)
  File "/usr/lib/python3.5/socketserver.py", line 354, in finish_request
    self.RequestHandlerClass(request, client_address, self)
  File "/usr/lib/python3.5/socketserver.py", line 681, in __init__
    self.handle()
  File "/usr/local/lib/python3.5/dist-packages/django/core/servers/basehttp.py", line 154, in handle
    handler.run(self.server.get_app())
  File "/usr/lib/python3.5/wsgiref/handlers.py", line 144, in run
    self.close()
  File "/usr/lib/python3.5/wsgiref/simple_server.py", line 36, in close
    self.status.split(' ',1)[0], self.bytes_sent
AttributeError: 'NoneType' object has no attribute 'split'
[27/Mar/2018 21:12:09] "GET /receive?signature=9a92f7ceef67943a025d4ba46f5cced9c2803a7f&echostr=3579162730822526825&timestamp=1522156329&nonce=3525708293 HTTP/1.0" 200 19
Internal Server Error: /receive
Traceback (most recent call last):
  File "/usr/local/lib/python3.5/dist-packages/django/utils/datastructures.py", line 77, in __getitem__
    list_ = super().__getitem__(key)
KeyError: 'echostr'

During handling of the above exception, another exception occurred:

Traceback (most recent call last):
  File "/home/WeWallProject/WeWall/views.py", line 17, in receive
    echostr = request.GET['echostr'];
  File "/usr/local/lib/python3.5/dist-packages/django/utils/datastructures.py", line 79, in __getitem__
    raise MultiValueDictKeyError(key)
django.utils.datastructures.MultiValueDictKeyError: 'echostr'

During handling of the above exception, another exception occurred:

Traceback (most recent call last):
  File "/usr/local/lib/python3.5/dist-packages/django/core/handlers/exception.py", line 35, in inner
    response = get_response(request)
  File "/usr/local/lib/python3.5/dist-packages/django/core/handlers/base.py", line 128, in _get_response
    response = self.process_exception_by_middleware(e, request)
  File "/usr/local/lib/python3.5/dist-packages/django/core/handlers/base.py", line 126, in _get_response
    response = wrapped_callback(request, *callback_args, **callback_kwargs)
  File "/home/WeWallProject/WeWall/views.py", line 26, in receive
    xml_tree = ET.fromstring(xml)
  File "/usr/lib/python3.5/xml/etree/ElementTree.py", line 1334, in XML
    return parser.close()
  File "<string>", line None
xml.etree.ElementTree.ParseError: no element found: line 1, column 0
[27/Mar/2018 21:13:08] "GET /receive HTTP/1.1" 500 76124
Internal Server Error: /receive
Traceback (most recent call last):
  File "/usr/local/lib/python3.5/dist-packages/django/utils/datastructures.py", line 77, in __getitem__
    list_ = super().__getitem__(key)
KeyError: 'echostr'

During handling of the above exception, another exception occurred:

Traceback (most recent call last):
  File "/home/WeWallProject/WeWall/views.py", line 17, in receive
    echostr = request.GET['echostr'];
  File "/usr/local/lib/python3.5/dist-packages/django/utils/datastructures.py", line 79, in __getitem__
    raise MultiValueDictKeyError(key)
django.utils.datastructures.MultiValueDictKeyError: 'echostr'

During handling of the above exception, another exception occurred:

Traceback (most recent call last):
  File "/usr/local/lib/python3.5/dist-packages/django/core/handlers/exception.py", line 35, in inner
    response = get_response(request)
  File "/usr/local/lib/python3.5/dist-packages/django/core/handlers/base.py", line 128, in _get_response
    response = self.process_exception_by_middleware(e, request)
  File "/usr/local/lib/python3.5/dist-packages/django/core/handlers/base.py", line 126, in _get_response
    response = wrapped_callback(request, *callback_args, **callback_kwargs)
  File "/home/WeWallProject/WeWall/views.py", line 26, in receive
    xml_tree = ET.fromstring(xml)
  File "/usr/lib/python3.5/xml/etree/ElementTree.py", line 1334, in XML
    return parser.close()
  File "<string>", line None
xml.etree.ElementTree.ParseError: no element found: line 1, column 0
[27/Mar/2018 21:13:08] "GET /receive HTTP/1.1" 500 76091
